<?xml version="1.0" ?>
<!-- =================================================================================== -->
<!-- |    This document was autogenerated by xacro from /root/aubo_ws/src/lara_aubo_robot/aubo_robot_ros/aubo_i5_description/urdf/aubo_i5.xacro | -->
<!-- |    EDITING THIS FILE BY HAND IS NOT RECOMMENDED                                 | -->
<!-- =================================================================================== -->
<robot name="aubo_i5">
    <transmission name="shoulder_pan_joint_trans">
        <type>transmission_interface/SimpleTransmission</type>
        <joint name="shoulder_pan_joint">
            <hardwareInterface>hardware_interface/PositionJointInterface</hardwareInterface>
        </joint>
        <actuator name="shoulder_pan_joint_motor">
            <mechanicalReduction>1</mechanicalReduction>
            <hardwareInterface>hardware_interface/PositionJointInterface</hardwareInterface>
        </actuator>
    </transmission>
    <transmission name="shoulder_lift_joint_trans">
        <type>transmission_interface/SimpleTransmission</type>
        <joint name="shoulder_lift_joint">
            <hardwareInterface>hardware_interface/PositionJointInterface</hardwareInterface>
        </joint>
        <actuator name="shoulder_lift_joint_motor">
            <mechanicalReduction>1</mechanicalReduction>
            <hardwareInterface>hardware_interface/PositionJointInterface</hardwareInterface>
        </actuator>
    </transmission>
    <transmission name="elbow_joint_trans">
        <type>transmission_interface/SimpleTransmission</type>
        <joint name="elbow_joint">
            <hardwareInterface>hardware_interface/PositionJointInterface</hardwareInterface>
        </joint>
        <actuator name="elbow_joint_motor">
            <mechanicalReduction>1</mechanicalReduction>
            <hardwareInterface>hardware_interface/PositionJointInterface</hardwareInterface>
        </actuator>
    </transmission>
    <transmission name="wrist_1_joint_trans">
        <type>transmission_interface/SimpleTransmission</type>
        <joint name="wrist_1_joint">
            <hardwareInterface>hardware_interface/PositionJointInterface</hardwareInterface>
        </joint>
        <actuator name="wrist_1_joint_motor">
            <mechanicalReduction>1</mechanicalReduction>
            <hardwareInterface>hardware_interface/PositionJointInterface</hardwareInterface>
        </actuator>
    </transmission>
    <transmission name="wrist_2_joint_trans">
        <type>transmission_interface/SimpleTransmission</type>
        <joint name="wrist_2_joint">
            <hardwareInterface>hardware_interface/PositionJointInterface</hardwareInterface>
        </joint>
        <actuator name="wrist_2_joint_motor">
            <mechanicalReduction>1</mechanicalReduction>
            <hardwareInterface>hardware_interface/PositionJointInterface</hardwareInterface>
        </actuator>
    </transmission>
    <transmission name="wrist_3_joint_trans">
        <type>transmission_interface/SimpleTransmission</type>
        <joint name="wrist_3_joint">
            <hardwareInterface>hardware_interface/PositionJointInterface</hardwareInterface>
        </joint>
        <actuator name="wrist_3_joint_motor">
            <mechanicalReduction>1</mechanicalReduction>
            <hardwareInterface>hardware_interface/PositionJointInterface</hardwareInterface>
        </actuator>
    </transmission>
    <gazebo reference="base_link">
        <kp>1000000.0</kp>
        <kd>1.0</kd>
        <mu1>0.8</mu1>
        <mu2>0.8</mu2>
        <maxVel>0.0</maxVel>
        <minDepth>0.001</minDepth>
        <selfCollide>true</selfCollide>
        <plugin name="gazebo_ros_control">
            <robotNamespace>/</robotNamespace>
        </plugin>
    </gazebo>
    <gazebo reference="shoulder_link">
        <kp>1000000.0</kp>
        <kd>1.0</kd>
        <mu1>0.8</mu1>
        <mu2>0.8</mu2>
        <maxVel>0.0</maxVel>
        <minDepth>0.001</minDepth>
        <selfCollide>true</selfCollide>
    </gazebo>
    <gazebo reference="upper_arm_link">
        <kp>1000000.0</kp>
        <kd>1.0</kd>
        <mu1>0.8</mu1>
        <mu2>0.8</mu2>
        <maxVel>0.0</maxVel>
        <minDepth>0.001</minDepth>
        <selfCollide>true</selfCollide>
    </gazebo>
    <gazebo reference="forearm_link">
        <kp>1000000.0</kp>
        <kd>1.0</kd>
        <mu1>0.8</mu1>
        <mu2>0.8</mu2>
        <maxVel>0.0</maxVel>
        <minDepth>0.001</minDepth>
        <selfCollide>true</selfCollide>
    </gazebo>
    <gazebo reference="wrist_1_link">
        <kp>1000000.0</kp>
        <kd>1.0</kd>
        <mu1>0.8</mu1>
        <mu2>0.8</mu2>
        <maxVel>0.0</maxVel>
        <minDepth>0.001</minDepth>
        <selfCollide>true</selfCollide>
    </gazebo>
    <gazebo reference="wrist_2_link">
        <kp>1000000.0</kp>
        <kd>1.0</kd>
        <mu1>0.8</mu1>
        <mu2>0.8</mu2>
        <maxVel>0.0</maxVel>
        <minDepth>0.001</minDepth>
        <selfCollide>true</selfCollide>
    </gazebo>
    <gazebo reference="wrist_3_link">
        <kp>1000000.0</kp>
        <kd>1.0</kd>
        <mu1>0.8</mu1>
        <mu2>0.8</mu2>
        <maxVel>0.0</maxVel>
        <minDepth>0.001</minDepth>
        <selfCollide>true</selfCollide>
    </gazebo>
    <gazebo reference="shoulder_pan_joint">
        <kp>1000000.0</kp>
        <kd>1.0</kd>
        <mu1>0.8</mu1>
        <mu2>0.8</mu2>
        <maxVel>0.0</maxVel>
        <minDepth>0.001</minDepth>
        <selfCollide>true</selfCollide>
    </gazebo>
    <gazebo reference="shoulder_lift_joint">
        <kp>1000000.0</kp>
        <kd>1.0</kd>
        <mu1>0.8</mu1>
        <mu2>0.8</mu2>
        <maxVel>0.0</maxVel>
        <minDepth>0.001</minDepth>
        <selfCollide>true</selfCollide>
    </gazebo>
    <gazebo reference="elbow_joint">
        <kp>1000000.0</kp>
        <kd>1.0</kd>
        <mu1>0.8</mu1>
        <mu2>0.8</mu2>
        <maxVel>0.0</maxVel>
        <minDepth>0.001</minDepth>
        <selfCollide>true</selfCollide>
    </gazebo>
    <gazebo reference="wrist_1_joint">
        <kp>1000000.0</kp>
        <kd>1.0</kd>
        <mu1>0.8</mu1>
        <mu2>0.8</mu2>
        <maxVel>0.0</maxVel>
        <minDepth>0.001</minDepth>
        <selfCollide>true</selfCollide>
    </gazebo>
    <gazebo reference="wrist_2_joint">
        <kp>1000000.0</kp>
        <kd>1.0</kd>
        <mu1>0.8</mu1>
        <mu2>0.8</mu2>
        <maxVel>0.0</maxVel>
        <minDepth>0.001</minDepth>
        <selfCollide>true</selfCollide>
    </gazebo>
    <gazebo reference="wrist_3_joint">
        <kp>1000000.0</kp>
        <kd>1.0</kd>
        <mu1>0.8</mu1>
        <mu2>0.8</mu2>
        <maxVel>0.0</maxVel>
        <minDepth>0.001</minDepth>
        <selfCollide>true</selfCollide>
    </gazebo>
    <link name="base_link">
        <inertial>
            <origin rpy="0 0 0" xyz="5.280333978763784e-09 0.0015966894220128586 0.016570455971104445" />
            <mass value="1.4382166298722134" />
            <inertia ixx="0.003103" ixy="-0.0" ixz="-0.0" iyy="0.002858" iyz="-4.9e-05" izz="0.005531" />
        </inertial>
        <visual>
            <origin rpy="-1.5707963267948966 0 0" xyz="0 0 0" />
            <geometry>
                <mesh filename="package://aubo_i5_description/meshes/visual/base_link.dae" scale="0.001 0.001 0.001" />
            </geometry>
        </visual>
        <collision>
            <origin rpy="0 0 0" xyz="0 0 0" />
            <geometry>
                <mesh filename="package://aubo_i5_description/meshes/collision/base_link.stl" scale="0.001 0.001 0.001" />
            </geometry>
        </collision>
    </link>
    <link name="shoulder_link">
        <inertial>
            <origin rpy="0 0 0" xyz="-4.185040550529615e-07 -0.00538388048820414 0.06988520317439471" />
            <mass value="3.9977368906576385" />
            <inertia ixx="0.010612" ixy="-0.0" ixz="0.0" iyy="0.010271" iyz="0.000382" izz="0.007824" />
        </inertial>
        <visual>
            <origin rpy="-1.5707963267948966 0 0" xyz="0.0 -0.0 -0.0435" />
            <geometry>
                <mesh filename="package://aubo_i5_description/meshes/visual/shoulder_link.dae" scale="0.001 0.001 0.001" />
            </geometry>
        </visual>
        <collision>
            <origin rpy="0 0 0" xyz="0.0 -0.0 -0.0435" />
            <geometry>
                <mesh filename="package://aubo_i5_description/meshes/collision/shoulder_link.stl" scale="0.001 0.001 0.001" />
            </geometry>
        </collision>
    </link>
    <link name="upper_arm_link">
        <inertial>
            <origin rpy="0 0 0" xyz="4.5155821807648865e-10 -0.0717893986201179 0.20400016275508465" />
            <mass value="10.264360778757078" />
            <inertia ixx="0.367413" ixy="-0.0" ixz="1e-06" iyy="0.361705" iyz="-0.0" izz="0.024156" />
        </inertial>
        <visual>
            <origin rpy="-1.5707963267948966 0 0" xyz="0.0 0.062 -0.122" />
            <geometry>
                <mesh filename="package://aubo_i5_description/meshes/visual/upper_arm_link.dae" scale="0.001 0.001 0.001" />
            </geometry>
        </visual>
        <collision>
            <origin rpy="0 0 0" xyz="0.0 0.062 -0.122" />
            <geometry>
                <mesh filename="package://aubo_i5_description/meshes/collision/upper_arm_link.stl" scale="0.001 0.001 0.001" />
            </geometry>
        </collision>
    </link>
    <link name="forearm_link">
        <inertial>
            <origin rpy="0 0 0" xyz="-8.598904331136158e-08 0.03777959596600701 0.18625691250689058" />
            <mass value="5.717058820664718" />
            <inertia ixx="0.110129" ixy="-0.0" ixz="0.0" iyy="0.109705" iyz="-0.000971" izz="0.005171" />
        </inertial>
        <visual>
            <origin rpy="-1.5707963267948966 0 0" xyz="0.0 0.062 -0.53" />
            <geometry>
                <mesh filename="package://aubo_i5_description/meshes/visual/forearm_link.dae" scale="0.001 0.001 0.001" />
            </geometry>
        </visual>
        <collision>
            <origin rpy="0 0 0" xyz="0.0 0.062 -0.53" />
            <geometry>
                <mesh filename="package://aubo_i5_description/meshes/collision/forearm_link.stl" scale="0.001 0.001 0.001" />
            </geometry>
        </collision>
    </link>
    <link name="wrist_1_link">
        <inertial>
            <origin rpy="0 0 0" xyz="4.043690373112674e-07 -0.03781762705264109 0.010378004019249931" />
            <mass value="1.1959791801557391" />
            <inertia ixx="0.001481" ixy="0.0" ixz="0.0" iyy="0.001416" iyz="7.9e-05" izz="0.000986" />
        </inertial>
        <visual>
            <origin rpy="-1.5707963267948966 0 0" xyz="0.0 0.0795 -0.906" />
            <geometry>
                <mesh filename="package://aubo_i5_description/meshes/visual/wrist_1_link.dae" scale="0.001 0.001 0.001" />
            </geometry>
        </visual>
        <collision>
            <origin rpy="0 0 0" xyz="0.0 0.0795 -0.906" />
            <geometry>
                <mesh filename="package://aubo_i5_description/meshes/collision/wrist_1_link.stl" scale="0.001 0.001 0.001" />
            </geometry>
        </collision>
    </link>
    <link name="wrist_2_link">
        <inertial>
            <origin rpy="0 0 0" xyz="-3.835911159071275e-07 -0.010378293494720053 0.03781729945949308" />
            <mass value="1.195979134054204" />
            <inertia ixx="0.001481" ixy="0.0" ixz="0.0" iyy="0.000986" iyz="7.9e-05" izz="0.001416" />
        </inertial>
        <visual>
            <origin rpy="-1.5707963267948966 0 0" xyz="0.0 0.1215 -0.96656" />
            <geometry>
                <mesh filename="package://aubo_i5_description/meshes/visual/wrist_2_link.dae" scale="0.001 0.001 0.001" />
            </geometry>
        </visual>
        <collision>
            <origin rpy="0 0 0" xyz="0.0 0.1215 -0.96656" />
            <geometry>
                <mesh filename="package://aubo_i5_description/meshes/collision/wrist_2_link.stl" scale="0.001 0.001 0.001" />
            </geometry>
        </collision>
    </link>
    <link name="wrist_3_link">
        <inertial>
            <origin rpy="0 0 0" xyz="4.15409377624965e-09 -0.01855349466746148 0.0003522591384534923" />
            <mass value="0.19247764025253766" />
            <inertia ixx="0.000104" ixy="0.0" ixz="-0.0" iyy="0.000169" iyz="-1e-06" izz="0.000101" />
        </inertial>
        <visual>
            <origin rpy="-1.5707963267948966 0 0" xyz="0.0 0.18206 -1.00856" />
            <geometry>
                <mesh filename="package://aubo_i5_description/meshes/visual/wrist_3_link.dae" scale="0.001 0.001 0.001" />
            </geometry>
        </visual>
        <collision>
            <origin rpy="0 0 0" xyz="0.0 0.18206 -1.00856" />
            <geometry>
                <mesh filename="package://aubo_i5_description/meshes/collision/wrist_3_link.stl" scale="0.001 0.001 0.001" />
            </geometry>
        </collision>
    </link>
    <link name="tool0_link" />
    <link name="tcp_link" />
    <joint name="base_joint" type="fixed">
        <parent link="world" />
        <child link="base_link" />
        <origin rpy="0 0 0" xyz="0 0 0" />
    </joint>
    <joint name="shoulder_pan_joint" type="revolute">
        <origin rpy="0 0 0" xyz="0.0 0.0 0.0435" />
        <parent link="base_link" />
        <child link="shoulder_link" />
        <axis xyz="-0.0 0.0 1.0" />
        <limit effort="300.0" lower="-3.04" upper="3.04" velocity="3.141592653589793" />
    </joint>
    <joint name="shoulder_lift_joint" type="revolute">
        <origin rpy="0 0 0" xyz="0.0 -0.062 0.0785" />
        <parent link="shoulder_link" />
        <child link="upper_arm_link" />
        <axis xyz="-0.0 -1.0 0.0" />
        <limit effort="300.0" lower="-3.04" upper="3.04" velocity="3.141592653589793" />
    </joint>
    <joint name="elbow_joint" type="revolute">
        <origin rpy="0 0 0" xyz="0.0 0.0 0.408" />
        <parent link="upper_arm_link" />
        <child link="forearm_link" />
        <axis xyz="-0.0 1.0 -0.0" />
        <limit effort="300.0" lower="-3.04" upper="3.04" velocity="3.141592653589793" />
    </joint>
    <joint name="wrist_1_joint" type="revolute">
        <origin rpy="0 0 0" xyz="0.0 -0.0175 0.376" />
        <parent link="forearm_link" />
        <child link="wrist_1_link" />
        <axis xyz="-0.0 -1.0 0.0" />
        <limit effort="50.0" lower="-3.04" upper="3.04" velocity="3.141592653589793" />
    </joint>
    <joint name="wrist_2_joint" type="revolute">
        <origin rpy="0 0 0" xyz="0.0 -0.042 0.06056" />
        <parent link="wrist_1_link" />
        <child link="wrist_2_link" />
        <axis xyz="-0.0 0.0 1.0" />
        <limit effort="50.0" lower="-3.04" upper="3.04" velocity="3.141592653589793" />
    </joint>
    <joint name="wrist_3_joint" type="revolute">
        <origin rpy="0 0 0" xyz="0.0 -0.06056 0.042" />
        <parent link="wrist_2_link" />
        <child link="wrist_3_link" />
        <axis xyz="-0.0 -1.0 0.0" />
        <limit effort="50.0" lower="-3.04" upper="3.04" velocity="3.141592653589793" />
    </joint>
    <joint name="tool0_joint" type="fixed">
        <parent link="wrist_3_link" />
        <child link="tool0_link" />
        <origin rpy="1.5707963267948966 0 0" xyz="0.0 -0.0335 0.0" />
    </joint>
    <joint name="tcp_joint" type="fixed">
        <parent link="tool0_link" />
        <child link="tcp_link" />
        <origin rpy="-3.141592653589793 0 1.5707963267948966" xyz="0.0 0.0 0" />
    </joint>
    <link name="world" />
    <gazebo>
        <plugin filename="libgazebo_ros_control.so" name="ros_control" />
    </gazebo>
</robot>

