<?xml version="1.0"?>
<robot name="aubo_i5">
  <link name="world" />
  
  <!-- LINKS -->
  <link name="base_link"/>
  <link name="shoulder_link"/>
  <link name="upper_arm_link"/>
  <link name="forearm_link"/>
  <link name="wrist_1_link"/>
  <link name="wrist_2_link"/>
  <link name="wrist_3_link"/>
  <link name="ee_link"/>

  <!--JOINTS -->
  <joint name="shoulder_pan_joint" type="revolute">
    <origin rpy="0 0 3.1416" xyz="0 0 0.122" />
    <parent link="base_link" />
    <child link="shoulder_link"/>
    <axis xyz="0 0 1" />
    <limit effort="300.0" lower="-3.04" upper="3.04" velocity="3.141592653589793" />
  </joint>
  <joint name="shoulder_lift_joint" type="revolute">
    <origin rpy="-1.5708 -1.5708 0" xyz="0 0.1215 0" />
    <parent link="shoulder_link" />
    <child link="upper_arm_link" />
    <axis xyz="0 0 1" />
    <limit effort="300.0" lower="-3.04" upper="3.04" velocity="3.141592653589793" />
  </joint>
  <joint name="elbow_joint" type="revolute">
    <origin rpy="-3.1416 -5.1632E-18 -5.459E-16" xyz="0.408 0 0" />
    <parent link="upper_arm_link" />
    <child link="forearm_link"/>
    <axis xyz="0 0 1" />
    <limit effort="300.0" lower="-3.04" upper="3.04" velocity="3.141592653589793" />
  </joint>
  <joint name="wrist_1_joint" type="revolute">
    <origin rpy="3.1416 -1.8323E-15 1.5708" xyz="0.376    0 0" />
    <parent link="forearm_link" />
    <child link="wrist_1_link"/>
    <axis xyz="0 0 1" />
    <limit effort="50.0" lower="-3.04" upper="3.04" velocity="3.141592653589793" />
  </joint>
  <joint name="wrist_2_joint" type="revolute">
    <origin rpy="-1.5708 -1.8709E-15 -1.6653E-16" xyz="   0 0.1025 0" />
    <parent link="wrist_1_link" />
    <child link="wrist_2_link"/>
    <axis xyz="0 0 1" />
    <limit effort="50.0" lower="-3.04" upper="   3.04" velocity="3.141592653589793" />
  </joint>
  <joint name="wrist_3_joint" type="revolute">
    <origin rpy="1.5708 0 1.7907E-15" xyz="0 -0.094 0"/>
    <parent link="wrist_2_link" />
    <child link="wrist_3_link" />
    <axis xyz="0 0 1" />
    <limit effort="50.0" lower="-3.04" upper="3.04" velocity="3.141592653589793" />
  </joint>

  <joint name="ee_fixed_joint" type="fixed">
    <parent link="wrist_3_link"/>
    <child link="ee_link" />
    <origin rpy="3.141592653589793 -1.5707963267948966    1.5707963267948966" xyz="0.0 0.0 0.0" />
  </joint>
  <joint name="base_joint" type="fixed">
    <parent link="world" />
    <child link="base_link" />
    <origin rpy="0.0 0.0 0.0" xyz="0.0 0.0 0.0" />
  </joint>
</robot>